<?xml version="1.0"?>
<robot name="my_robot" xmlns:xacro="http://ros.org/wiki/xacro">

  <material name="blue"><color rgba="0 0 1 1"/></material>
  <material name="black"><color rgba="0 0 0 1"/></material>

  <link name="base_footprint"/>

  <link name="base_link">
    <visual>
      <geometry>
        <box size="0.4 0.4 0.2"/>
      </geometry>
      <material name="blue"/>
    </visual>
    <collision>
      <geometry>
        <box size="0.4 0.4 0.2"/>
      </geometry>
    </collision>
    <inertial>
      <mass value="2.0"/>
      <inertia ixx="0.1" ixy="0.0" ixz="0.0"
               iyy="0.1" iyz="0.0"
               izz="0.1"/>
    </inertial>
  </link>

  <joint name="base_footprint_joint" type="fixed">
    <parent link="base_footprint"/>
    <child link="base_link"/>
    <origin xyz="0 0 0.1"/>
  </joint>

  <xacro:macro name="wheel" params="name x y">
    <link name="${name}">
      <visual>
        <geometry>
          <cylinder radius="0.05" length="0.02"/>
        </geometry>
        <origin xyz="0 0 0" rpy="1.5708 0 0"/> 
        <material name="black"/>
      </visual>
      <collision>
        <geometry>
          <cylinder radius="0.05" length="0.02"/>
        </geometry>
        <origin xyz="0 0 0" rpy="1.5708 0 0"/>
      </collision>
      <inertial>
        <mass value="0.2"/>
        <inertia ixx="0.001" ixy="0.0" ixz="0.0"
                 iyy="0.001" iyz="0.0"
                 izz="0.001"/>
      </inertial>
    </link>

    <joint name="${name}_joint" type="continuous">
      <parent link="base_link"/>
      <child link="${name}"/>
      <origin xyz="${x} ${y} -0.05" rpy="0 0 0"/>
      <axis xyz="0 1 0"/>
    </joint>
  </xacro:macro>

  <xacro:wheel name="front_left_wheel"  x="0.15"  y="0.2"/>
  <xacro:wheel name="front_right_wheel" x="0.15"  y="-0.2"/>
  <xacro:wheel name="rear_left_wheel"   x="-0.15" y="0.2"/>
  <xacro:wheel name="rear_right_wheel"  x="-0.15" y="-0.2"/>

</robot>

